<?xml version="1.0" ?>
<sdf version='1.7'>
    <model name='prius_hybrid'>
        <pose>25.88 -17.5 0.04 0 -0 1.57</pose>
        <link name='chassis'>
        <pose>0 0 0 0 -0 1.57</pose>
        <inertial>
            <mass>1326</mass>
            <pose>0 -0.266 0.48 0 -0 0</pose>
            <inertia>
                <ixx>2581.13</ixx>
                <ixy>0</ixy>
                <iyy>591.308</iyy>
                <ixz>0</ixz>
                <iyz>0</iyz>
                <izz>2681.95</izz>
            </inertia>
        </inertial>
        <visual name='chassis_visual'>
            <geometry>
                <mesh>
                    <uri>model://prius_hybrid/meshes/Hybrid.obj</uri>
                    <scale>0.01 0.01 0.01</scale>
                    <submesh>
                        <name>Hybrid</name>
                        <center>0</center>
                    </submesh>
                </mesh>
            </geometry>
        </visual>
        <visual name='interior_visual'>
            <geometry>
                <mesh>
                    <uri>model://prius_hybrid/meshes/Hybrid.obj</uri>
                    <scale>0.01 0.01 0.01</scale>
                    <submesh>
                        <name>Hybrid_Interior</name>
                        <center>0</center>
                    </submesh>
                </mesh>
            </geometry>
        </visual>
        <visual name='windows_visual'>
            <geometry>
                <mesh>
                    <uri>model://prius_hybrid/meshes/Hybrid.obj</uri>
                    <scale>0.01 0.01 0.01</scale>
                    <submesh>
                        <name>Hybrid_Windows</name>
                        <center>0</center>
                    </submesh>
                </mesh>
            </geometry>
        </visual>
        <collision name='chassis'>
            <pose>0 0.05 0.625 0 -0 0</pose>
            <geometry>
                <box>
                    <size>1.7526 2.1 0.95</size>
                </box>
            </geometry>
        </collision>
        <collision name='front_bumper'>
            <pose>0 -2 0.458488 0 -0 0</pose>
            <geometry>
                <box>
                    <size>1.33728 0.48 0.566691</size>
                </box>
            </geometry>
        </collision>
        <collision name='hood'>
            <pose>0 -1.90084 0.676305 0.341247 -0 0</pose>
            <geometry>
                <box>
                    <size>1.59797 0.493107 0.265468</size>
                </box>
            </geometry>
        </collision>
        <collision name='windshield'>
            <pose>0 -0.875105 1.03227 0.335476 -0 0</pose>
            <geometry>
                <box>
                    <size>1.16838 1.65425 0.272347</size>
                </box>
            </geometry>
        </collision>
        <collision name='top_front'>
            <pose>0 0.161236 1.38604 0.13503 -0 0</pose>
            <geometry>
                <box>
                    <size>1.27915 0.625988 0.171868</size>
                </box>
            </geometry>
        </collision>
        <collision name='top_rear'>
            <pose>0 0.817696 1.36007 -0.068997 0 0</pose>
            <geometry>
                <box>
                    <size>1.28513 0.771189 0.226557</size>
                </box>
            </geometry>
        </collision>
        <collision name='rear_window'>
            <pose>0 1.64053 1.17513 -0.262017 0 0</pose>
            <geometry>
                <box>
                    <size>1.26785 1.11634 0.244286</size>
                </box>
            </geometry>
        </collision>
        <collision name='trunk'>
            <pose>0 1.63706 0.88818 0 -0 0</pose>
            <geometry>
                <box>
                    <size>1.78806 1.13899 0.482746</size>
                </box>
            </geometry>
        </collision>
        <collision name='back_bumper'>
            <pose>0 2.05445 0.57787 0 -0 0</pose>
            <geometry>
                <box>
                    <size>1.78165 0.512093 0.581427</size>
                </box>
            </geometry>
        </collision>
        </link>
        <link name='steering_wheel'>
        <pose>0.627868 0.357734 0.988243 -1.3021 -0 1.57</pose>
        <inertial>
            <mass>1</mass>
            <inertia>
                <ixx>0.145833</ixx>
                <ixy>0</ixy>
                <ixz>0</ixz>
                <iyy>0.145833</iyy>
                <iyz>0</iyz>
                <izz>0.125</izz>
            </inertia>
        </inertial>
        <collision name='collision'>
            <geometry>
                <cylinder>
                    <radius>0.178172</radius>
                    <length>0.041845</length>
                </cylinder>
            </geometry>
            <surface>
                <contact>
                    <ode>
                        <min_depth>0.003</min_depth>
                    </ode>
                </contact>
            </surface>
        </collision>
        <visual name='visual'>
            <pose>0 0 0 1.3021 -0 0</pose>
            <geometry>
                <mesh>
                    <uri>model://prius_hybrid/meshes/Hybrid.obj</uri>
                    <scale>0.01 0.01 0.01</scale>
                    <submesh>
                        <name>Steering_Wheel</name>
                        <center>1</center>
                    </submesh>
                </mesh>
            </geometry>
        </visual>
        </link>
        <link name='front_left_wheel'>
        <pose>1.41 0.76 0.3 0 -0 1.57</pose>
        <inertial>
            <mass>11</mass>
            <inertia>
                <ixx>0.586312</ixx>
                <ixy>0</ixy>
                <iyy>0.335529</iyy>
                <ixz>0</ixz>
                <iyz>0</iyz>
                <izz>0.335529</izz>
            </inertia>
        </inertial>
        <visual name='visual'>
            <pose>0.04 0 0 0 -0 0</pose>
            <geometry>
                <mesh>
                    <uri>model://prius_hybrid/meshes/Hybrid.obj</uri>
                    <scale>0.01 0.01 0.01</scale>
                    <submesh>
                        <name>Wheel_Front_Left_</name>
                        <center>1</center>
                    </submesh>
                </mesh>
            </geometry>
        </visual>
        <collision name='collision'>
            <pose>0 0 0 0 1.5708 0</pose>
            <geometry>
                <sphere>
                    <radius>0.31265</radius>
                </sphere>
            </geometry>
            <surface>
                <friction>
                    <ode>
                        <mu>0.9</mu>
                        <mu2>0.9</mu2>
                        <slip1>0</slip1>
                        <slip2>0</slip2>
                    </ode>
                </friction>
                <contact>
                    <ode>
                        <min_depth>0.001</min_depth>
                        <kp>1e+09</kp>
                    </ode>
                </contact>
            </surface>
        </collision>
        </link>
        <link name='front_right_wheel'>
        <pose>1.41 -0.76 0.3 0 -0 1.57</pose>
        <inertial>
            <mass>11</mass>
            <inertia>
                <ixx>0.586312</ixx>
                <ixy>0</ixy>
                <iyy>0.335529</iyy>
                <ixz>0</ixz>
                <iyz>0</iyz>
                <izz>0.335529</izz>
            </inertia>
        </inertial>
        <visual name='visual'>
            <pose>-0.04 0 0 0 -0 0</pose>
            <pose>0 0 0 0 -0 0</pose>
            <geometry>
                <mesh>
                    <uri>model://prius_hybrid/meshes/Hybrid.obj</uri>
                    <scale>0.01 0.01 0.01</scale>
                    <submesh>
                        <name>Wheel_Front_Right</name>
                        <center>1</center>
                    </submesh>
                </mesh>
            </geometry>
        </visual>
        <collision name='collision'>
            <pose>0 0 0 0 1.5708 0</pose>
            <geometry>
                <sphere>
                    <radius>0.31265</radius>
                </sphere>
            </geometry>
            <surface>
                <friction>
                    <ode>
                        <mu>0.9</mu>
                        <mu2>0.9</mu2>
                        <slip1>0</slip1>
                        <slip2>0</slip2>
                    </ode>
                </friction>
                <contact>
                    <ode>
                        <min_depth>0.001</min_depth>
                        <kp>1e+09</kp>
                    </ode>
                </contact>
            </surface>
        </collision>
        </link>
        <link name='rear_left_wheel'>
        <pose>-1.45 0.786 0.3 0 -0 1.57</pose>
        <inertial>
            <mass>11</mass>
            <inertia>
                <ixx>0.586312</ixx>
                <ixy>0</ixy>
                <iyy>0.335529</iyy>
                <ixz>0</ixz>
                <iyz>0</iyz>
                <izz>0.335529</izz>
            </inertia>
        </inertial>
        <visual name='visual'>
            <pose>0.04 0 0 0 -0 0</pose>
            <geometry>
                <mesh>
                    <uri>model://prius_hybrid/meshes/Hybrid.obj</uri>
                    <scale>0.01 0.01 0.01</scale>
                    <submesh>
                        <name>Wheel_Front_Left_</name>
                        <center>1</center>
                    </submesh>
                </mesh>
            </geometry>
        </visual>
        <collision name='collision'>
            <pose>0 0 0 0 1.5708 0</pose>
            <geometry>
                <sphere>
                    <radius>0.31265</radius>
                </sphere>
            </geometry>
            <surface>
                <friction>
                    <ode>
                        <mu>1.1</mu>
                        <mu2>1.1</mu2>
                        <slip1>0</slip1>
                        <slip2>0</slip2>
                    </ode>
                </friction>
                <contact>
                    <ode>
                        <min_depth>0.001</min_depth>
                        <kp>1e+09</kp>
                    </ode>
                </contact>
            </surface>
        </collision>
        </link>
        <link name='rear_right_wheel'>
        <pose>-1.45 -0.786 0.3 0 -0 1.57</pose>
        <inertial>
            <mass>11</mass>
            <inertia>
                <ixx>0.586312</ixx>
                <ixy>0</ixy>
                <iyy>0.335529</iyy>
                <ixz>0</ixz>
                <iyz>0</iyz>
                <izz>0.335529</izz>
            </inertia>
        </inertial>
        <visual name='visual'>
            <pose>-0.04 0 0 0 -0 0</pose>
            <geometry>
                <mesh>
                    <uri>model://prius_hybrid/meshes/Hybrid.obj</uri>
                    <scale>0.01 0.01 0.01</scale>
                    <submesh>
                        <name>Wheel_Front_Right</name>
                        <center>1</center>
                    </submesh>
                </mesh>
            </geometry>
        </visual>
        <collision name='collision'>
            <pose>0 0 0 0 1.5708 0</pose>
            <geometry>
                <sphere>
                    <radius>0.31265</radius>
                </sphere>
            </geometry>
            <surface>
                <friction>
                    <ode>
                        <mu>1.1</mu>
                        <mu2>1.1</mu2>
                        <slip1>0</slip1>
                        <slip2>0</slip2>
                    </ode>
                </friction>
                <contact>
                    <ode>
                        <min_depth>0.001</min_depth>
                        <kp>1e+09</kp>
                    </ode>
                </contact>
            </surface>
        </collision>
        </link>
        <joint name='front_left_combined_joint' type='universal'>
            <pose>0 0 0 -0.087266 0 0</pose>
            <child>front_left_wheel</child>
            <parent>chassis</parent>
            <axis>
                <xyz>0 0 1</xyz>
                <limit>
                    <lower>-0.8727</lower>
                    <upper>0.8727</upper>
                </limit>
            </axis>
            <axis2>
                <xyz>1 0 0</xyz>
                <dynamics>
                    <friction>18.0474</friction>
                    <spring_reference>0</spring_reference>
                    <spring_stiffness>0</spring_stiffness>
                </dynamics>
                <limit />
            </axis2>
        </joint>
        <joint name='front_right_combined_joint' type='universal'>
            <pose>0 0 0 -0.087266 0 0</pose>
            <child>front_right_wheel</child>
            <parent>chassis</parent>
            <axis>
                <xyz>0 0 1</xyz>
                <limit>
                    <lower>-0.8727</lower>
                    <upper>0.8727</upper>
                </limit>
            </axis>
            <axis2>
                <xyz>1 0 0</xyz>
                <dynamics>
                    <friction>18.0474</friction>
                    <spring_reference>0</spring_reference>
                    <spring_stiffness>0</spring_stiffness>
                </dynamics>
                <limit />
            </axis2>
        </joint>
        <link name='rear_axle'>
        <pose>-1.45 0 0.3 0 -0 0</pose>
        <inertial>
            <mass>30</mass>
            <inertia>
                <ixx>0.084375</ixx>
                <ixy>0</ixy>
                <iyy>4.64581</iyy>
                <ixz>0</ixz>
                <iyz>0</iyz>
                <izz>4.64581</izz>
            </inertia>
        </inertial>
        <visual name='visual'>
            <pose>0 0 0 0 1.5708 0</pose>
            <geometry>
                <cylinder>
                    <length>1.357</length>
                    <radius>0.075</radius>
                </cylinder>
            </geometry>
            <material>
                <script>
                    <name> Gazebo / Grey </name>
                        <uri> file: //media/materials/scripts/gazebo.material</uri>
                </script>
            </material>
        </visual>
        </link>
        <joint name='rear_axle_joint' type='revolute'>
            <child>rear_axle</child>
            <parent>chassis</parent>
            <axis>
                <xyz>0 1 0</xyz>
                <limit>
                    <lower>-0.0508906</lower>
                    <upper>0.0508906</upper>
                </limit>
                <dynamics>
                    <spring_stiffness>20000</spring_stiffness>
                    <damping>2000</damping>
                    <spring_reference>0</spring_reference>
                </dynamics>
            </axis>
        </joint>
        <joint name='rear_left_wheel_joint' type='revolute'>
            <child>rear_left_wheel</child>
            <parent>rear_axle</parent>
            <axis>
                <xyz>1 0 0</xyz>
                <dynamics>
                    <friction>12.0316</friction>
                    <spring_reference>0</spring_reference>
                    <spring_stiffness>0</spring_stiffness>
                </dynamics>
                <limit>
                    <lower>-1e+16</lower>
                    <upper>1e+16</upper>
                </limit>
            </axis>
        </joint>
        <joint name='rear_right_wheel_joint' type='revolute'>
            <child>rear_right_wheel</child>
            <parent>rear_axle</parent>
            <axis>
                <xyz>1 0 0</xyz>
                <dynamics>
                    <friction>12.0316</friction>
                    <spring_reference>0</spring_reference>
                    <spring_stiffness>0</spring_stiffness>
                </dynamics>
                <limit>
                    <lower>-1e+16</lower>
                    <upper>1e+16</upper>
                </limit>
            </axis>
        </joint>
        <joint name='steering_joint' type='revolute'>
            <pose>-0.002 0 0 0 -0 0</pose>
            <parent>chassis</parent>
            <child>steering_wheel</child>
            <axis>
                <xyz expressed_in='__model__'>-0.964118 0.000768 0.265556</xyz>
                <limit>
                    <lower>-7.85</lower>
                    <upper>7.85</upper>
                </limit>
                <dynamics>
                    <damping>1</damping>
                    <spring_reference>0</spring_reference>
                    <spring_stiffness>0</spring_stiffness>
                </dynamics>
            </axis>
            <physics>
                <ode>
                    <cfm_damping>1</cfm_damping>
                </ode>
            </physics>
        </joint>

        <link name='camera_link'>
        <pose>2.1 0 0.8 0 -0 0</pose>
        <visual name='visual'>
            <geometry>
                <box>
                    <size>0.1 0.1 0.1</size>
                </box>
            </geometry>
        </visual>
        </link>
        <link name='camera_rgb_optical_frame'>
        <inertial>
            <pose>0 0 0 0 0 0</pose>
            <inertia>
                <ixx>0.001</ixx>
                <ixy>0.000</ixy>
                <ixz>0.000</ixz>
                <iyy>0.001</iyy>
                <iyz>0.000</iyz>
                <izz>0.001</izz>
            </inertia>
            <mass>0.035</mass>
        </inertial>
        <pose>4.6 1.3 0.1 0 0.78 0</pose>
        <sensor name='camera1' type='camera'>
            <always_on>1</always_on>
            <visualize>1</visualize>
            <update_rate>10</update_rate>
            <camera name='picam'>
                <horizontal_fov>1.0856</horizontal_fov>
                <image>
                    <width>640</width>
                    <height>480</height>
                    <format>R8G8B8</format>
                </image>
                <clip>
                    <near>0.03</near>
                    <far>100</far>
                </clip>
                <noise>
                    <type>gaussian</type>
                    <mean>0</mean>
                    <stddev>0.007</stddev>
                </noise>
            </camera>
            <plugin name="camera_driver" filename="libgazebo_ros_camera.so">
                    <ros>
                        <!-- namespace>camera_driver_PR002</namespace -->
                        <remapping>image_raw:=image_demo</remapping>
                        <remapping>camera_info:=camera_info_demo</remapping>
                    </ros>
                    <!-- camera_name>omit so it defaults to sensor name</camera_name not used -->
                    <!-- frame_name>omit so it defaults to link name</frameName not used -->
                    <!-- <hack_baseline>0.07</hack_baseline>  not used -->
        </plugin>
        </sensor>
        </link>
        <joint name='camera_joint' type='fixed'>
            <parent>chassis</parent>
            <child>camera_link</child>
            <pose>0 0 0 0 -0 0</pose>
            <axis>
                <xyz>0 0 1</xyz>
                <limit>
                    <lower>-1e+16</lower>
                    <upper>1e+16</upper>
                </limit>
            </axis>
        </joint>
        <joint name='camera_rgb_joint' type='fixed'>
            <parent>camera_link</parent>
            <child>camera_rgb_optical_frame</child>
            <pose>0 0 0 0 -0 0</pose>
            <axis>
                <xyz>0 0 1</xyz>
                <limit>
                    <lower>-1e+16</lower>
                    <upper>1e+16</upper>
                </limit>
            </axis>
        </joint>
        <link name='camera_link2'>
        <pose>2 0.7 0.8 0 -0 0</pose>
        <visual name='visual'>
            <geometry>
                <box>
                    <size>0.1 0.1 0.1</size>
                </box>
            </geometry>
        </visual>
        </link>
        <link name='camera_rgb_optical_frame2'>
        <inertial>
            <pose>0 0 0 0 -0 0</pose>
            <inertia>
                <ixx>0.001</ixx>
                <ixy>0</ixy>
                <ixz>0</ixz>
                <iyy>0.001</iyy>
                <iyz>0</iyz>
                <izz>0.001</izz>
            </inertia>
            <mass>0.035</mass>
        </inertial>
        <pose>2 0.7 0.8 0 0.5 1.57</pose>
        <sensor name='camera2' type='camera'>
            <always_on>1</always_on>
            <visualize>1</visualize>
            <update_rate>10</update_rate>
            <camera name='picam'>
                <horizontal_fov>1.0856</horizontal_fov>
                <image>
                    <width>640</width>
                    <height>480</height>
                    <format>R8G8B8</format>
                </image>
                <clip>
                    <near>0.03</near>
                    <far>100</far>
                </clip>
                <noise>
                    <type>gaussian</type>
                    <mean>0</mean>
                    <stddev>0.007</stddev>
                </noise>
            </camera>
            <plugin name="camera_driver" filename="libgazebo_ros_camera.so">
                    <ros>
                        <!-- namespace>camera_driver_PR002</namespace -->
                        <remapping>image_raw:=image_demo</remapping>
                        <remapping>camera_info:=camera_info_demo</remapping>
                    </ros>
                    <!-- camera_name>omit so it defaults to sensor name</camera_name not used -->
                    <!-- frame_name>omit so it defaults to link name</frameName not used -->
                    <!-- <hack_baseline>0.07</hack_baseline>  not used -->
        </plugin>
        </sensor>
        </link>
        <joint name='camera_joint2' type='fixed'>
            <parent>chassis</parent>
            <child>camera_link2</child>
            <pose>0 0 0 0 -0 0</pose>
            <axis>
                <xyz>0 0 1</xyz>
                <limit>
                    <lower>-1e+16</lower>
                    <upper>1e+16</upper>
                </limit>
            </axis>
        </joint>
        <joint name='camera_rgb_joint2' type='fixed'>
            <parent>camera_link2</parent>
            <child>camera_rgb_optical_frame2</child>
            <pose>0 0 0 0 -0 0</pose>
            <axis>
                <xyz>0 0 1</xyz>
                <limit>
                    <lower>-1e+16</lower>
                    <upper>1e+16</upper>
                </limit>
            </axis>
        </joint>
        <plugin name='ackermann_drive' filename='libgazebo_ros_ackermann_drive.so'>
            <ros>
                <namespace>PR002</namespace>
                <remapping>cmd_vel:=cmd_demo</remapping>
                <remapping>odom:=odom_demo</remapping>
                <remapping>distance:=distance_demo</remapping>
            </ros>
            <update_rate>100.0</update_rate>
            <front_left_joint>front_left_combined_joint</front_left_joint>
            <front_right_joint>front_right_combined_joint</front_right_joint>
            <rear_left_joint>rear_left_wheel_joint</rear_left_joint>
            <rear_right_joint>rear_right_wheel_joint</rear_right_joint>
            <left_steering_joint>front_left_combined_joint</left_steering_joint>
            <right_steering_joint>front_right_combined_joint</right_steering_joint>
            <steering_wheel_joint>steering_joint</steering_wheel_joint>
            <max_steer>0.6458</max_steer>
            <max_steering_angle>7.85</max_steering_angle>
            <max_speed>6</max_speed>
            <left_steering_pid_gain>1500 0 1</left_steering_pid_gain>
            <left_steering_i_range>0 0</left_steering_i_range>
            <right_steering_pid_gain>1500 0 1</right_steering_pid_gain>
            <right_steering_i_range>0 0</right_steering_i_range>
            <linear_velocity_pid_gain>1000 0 1</linear_velocity_pid_gain>
            <linear_velocity_i_range>0 0</linear_velocity_i_range>
            <publish_odom>1</publish_odom>
            <publish_odom_tf>1</publish_odom_tf>
            <publish_wheel_tf>1</publish_wheel_tf>
            <publish_distance>1</publish_distance>
            <odometry_frame>odom_demo</odometry_frame>
            <robot_base_frame>chassis</robot_base_frame>
        </plugin>

        <!-- Hokuyo Laser -->
        <link name="hokuyo_link">
            <pose> 0.2 0 1.5 0 0 0.3 </pose>
            <inertial>
                <inertia>
                    <ixx>1e-6</ixx>
                    <ixy>0</ixy>
                    <ixz>0</ixz>
                    <iyy>1e-6</iyy>
                    <iyz>0</iyz>
                    <izz>1e-6</izz>
                </inertia>
                <mass>1e-5</mass>
            </inertial>
            <collision name="collision">
                <pose>0 0 0.5 0 0 0</pose>
                <geometry>
                    <box>
                        <size>0.1 0.1 0.1</size>
                    </box>
                </geometry>
            </collision>
            <visual name="visual">
                <geometry>
                    <mesh>
                        <uri>model://hokuyo/meshes/hokuyo.dae</uri>
                    </mesh>
                </geometry>
            </visual>

            <sensor name="laser" type="gpu_ray">
                <pose>0.01 0 0.0175 0 -0 0</pose>
                <ray>
                    <scan>
                        <horizontal>
                            <samples>320</samples>
                            <resolution>5</resolution>  <!-- dafault: 1 -->
                            <min_angle>-1.00</min_angle>  <!-- 0.1 to 0.2, 0.13 -->
                            <max_angle>1.00</max_angle>
                        </horizontal>
                    </scan>
                    <range>
                        <min>0.08</min>
                        <max>8</max>
                    </range>
                </ray>


                <plugin name="laser" filename="libgazebo_ros_ray_sensor.so">
                    <ros>
                        <!-- <namespace>test_cam</namespace> -->
                        <!-- remapping>out:=scan</remapping -->
                        <remapping>~/out:=scan</remapping>
                        <!-- <remapping>camera_info:=camera_info_demo</remapping> -->
                    </ros>

                    <frame_name>laser_frame</frame_name>
                    <output_type>sensor_msgs/LaserScan</output_type>
                </plugin>
                <always_on>1</always_on>
                <update_rate>5</update_rate>  <!-- 10 -> 2 -->
                <visualize>1</visualize>
            </sensor>
        </link>

        <joint name="hokuyo_joint" type="revolute">
            <parent>chassis</parent>
            <child>hokuyo_link</child>
            <axis>
                <xyz>0 1 0</xyz>
                <limit>
                    <upper>0</upper>
                    <lower>0</lower>
                </limit>
            </axis>
        </joint>
    </model>
</sdf>
